Traceback (most recent call last):
  File "/Users/styczynski/Code/aadg-genomics-class/presentation/robustExternalize/robExt-5641ED547A3B3D832334BDBA740493F5.tex", line 95, in <module>
    rects = ax.bar(x + offset, dict(
  File "/Users/styczynski/.pyenv/versions/3.10.7/lib/python3.10/site-packages/matplotlib/__init__.py", line 1442, in inner
    return func(ax, *map(sanitize_sequence, args), **kwargs)
  File "/Users/styczynski/.pyenv/versions/3.10.7/lib/python3.10/site-packages/matplotlib/axes/_axes.py", line 2392, in bar
    self._process_unit_info(
  File "/Users/styczynski/.pyenv/versions/3.10.7/lib/python3.10/site-packages/matplotlib/axes/_base.py", line 2551, in _process_unit_info
    axis.update_units(data)
  File "/Users/styczynski/.pyenv/versions/3.10.7/lib/python3.10/site-packages/matplotlib/axis.py", line 1670, in update_units
    default = self.converter.default_units(data, self)
  File "/Users/styczynski/.pyenv/versions/3.10.7/lib/python3.10/site-packages/matplotlib/category.py", line 105, in default_units
    axis.set_units(UnitData(data))
  File "/Users/styczynski/.pyenv/versions/3.10.7/lib/python3.10/site-packages/matplotlib/category.py", line 181, in __init__
    self.update(data)
  File "/Users/styczynski/.pyenv/versions/3.10.7/lib/python3.10/site-packages/matplotlib/category.py", line 214, in update
    for val in OrderedDict.fromkeys(data):
TypeError: unhashable type: 'dict'
